Workbook
Name ______________________All1: '[1]Dbase - Spv'!$B$2:$T$238
Name ______________________All2: '[2]Gratuity DBase'!$A$2:$S$236
Name ______________________def2: #REF!
Name ______________________def3: #REF!
Name ______________________FEB2: [3]FEB2!$B$8:$C$100
Name ______________________JAN2: [3]JAN2!$B$8:$C$106
Name ______________________JC15: #REF!
Name ______________________Jnr1: '[4]P&T Dbase-Jnr Ewe'!$B$7:$AH$207
Name ______________________Jnr3: '[4]P&T Dbase-Jnr Shg'!$B$7:$IV$285
Name ______________________Jnr4: '[4]P&T Dbase-Jnr HQ'!$B$7:$IV$57
Name ______________________MAR1: [3]MAR1!$B$8:$C$100
Name ______________________MAR2: [3]MAR2!$B$8:$C$100
Name ______________________Mgt5: #REF!
Name ______________________PDA1: [5]PDS1!$B$1:$O$30
Name ______________________PDA2: [5]PDS2!$B$2:$N$100
Name ______________________Tax1: #REF!
Name ______________________Tax10: #REF!
Name ______________________Tax11: #REF!
Name ______________________TAX12: #REF!
Name ______________________TAX123: #REF!
Name ______________________tax1234: #REF!
Name ______________________tax12345: #REF!
Name ______________________Tax2: #REF!
Name ______________________TAX21: #REF!
Name ______________________Tax3: #REF!
Name ______________________Tax4: #REF!
Name ______________________Tax5: #REF!
Name ______________________Tax6: #REF!
Name ______________________Tax7: #REF!
Name ______________________Tax8: #REF!
Name ______________________Tax9: #REF!
Name ______________________tb1: #REF!
Name ______________________WHT1: [6]Sheet15!$A$4:$Q$31
Name _____________________All1: '[1]Dbase - Spv'!$B$2:$T$238
Name _____________________All2: '[2]Gratuity DBase'!$A$2:$S$236
Name _____________________def2: #REF!
Name _____________________def3: #REF!
Name _____________________def4: #REF!
Name _____________________def5: #REF!
Name _____________________FEB1: [3]FEB1!$B$8:$C$100
Name _____________________FEB2: [3]FEB2!$B$8:$C$100
Name _____________________JAN2: [3]JAN2!$B$8:$C$106
Name _____________________JC15: #REF!
Name _____________________Jnr1: '[4]P&T Dbase-Jnr Ewe'!$B$7:$AH$207
Name _____________________Jnr3: '[4]P&T Dbase-Jnr Shg'!$B$7:$IV$285
Name _____________________Jnr4: '[4]P&T Dbase-Jnr HQ'!$B$7:$IV$57
Name _____________________MAR1: [3]MAR1!$B$8:$C$100
Name _____________________MAR2: [3]MAR2!$B$8:$C$100
Name _____________________Mgt5: #REF!
Name _____________________PDA1: [5]PDS1!$B$1:$O$30
Name _____________________PDA2: [5]PDS2!$B$2:$N$100
Name _____________________PDA3: [7]PDS3!$B$2:$N$100
Name _____________________Tax1: #REF!
Name _____________________Tax10: #REF!
Name _____________________Tax11: #REF!
Name _____________________TAX12: #REF!
Name _____________________TAX123: #REF!
Name _____________________tax1234: #REF!
Name _____________________tax12345: #REF!
Name _____________________Tax2: #REF!

Sheet DASHBOARD

Sheet SPL
A1: BLISSFUL NIGERIA PLC
A2: STAMENT OF PROFIT OR LOSS FOR THE PERIOD ENDED 31ST DECEMBER, 2023
E4: NOTES
B5: REVENUE | E5: 1 | F5: =NOTES!D6 -> 4030173403
B6: COST OF SALE | E6: 2 | F6: =-NOTES!D13 -> -3277259249
B7: GROSS PROFIT | F7: =SUM(F5:F6) -> 752914154
B9: SELLING AND DISTRIBUTION EXPENSES | E9: 3 | F9: =-NOTES!D21 -> -15061576
B10: GENERAL AND ADMIN EXPENSES | E10: 4 | F10: =-NOTES!D52 -> -419862355
B11: EBITDA | F11: =SUM(F7:F10) -> 317990223
B13: FINANCE COST | E13: 5 | F13: =-NOTES!D57 -> -175276150
B14: PROFIT BEFORE TAX | F14: =SUM(F11:F13) -> 142714073
B16: INCOME TAX EXPENSE | E16: 6 | F16: =-NOTES!D62 -> -35687952
B17: PROFIT AFTER TAX | F17: =SUM(F14:F16) -> 107026121

Sheet SOFP
A1: BLISSFUL NIGERIA PLC
A2: STATEMENT OF FINANCIAL POSITION AS AT 31ST DECEMBER, 2023
F4: NOTES
B5: PROPERTY PLANTS AND EQUIPMENTS | F5: 7 | G5: =NOTES!G68 -> 91550265
B6: CAPITAL WORK IN PROGRESS | F6: 8 | G6: =NOTES!D73 -> 27525000
B7: NON CURRENT ASSET | G7: =SUM(G5:G6) -> 119075265
B9: TRADE AND OTHER RECIEVABLE | F9: 9 | G9: =NOTES!D77 -> 147630717
B10: CASH AND CASH EQUIVALENT | G10: =NOTES!D87 -> 266952955
B11: CURRENT ASSET | F11: 10 | G11: =SUM(G9:G10) -> 414583672
B13: TOTAL ASSET | G13: =G7+G11 -> 533658937
B15: EQUITY | G15: =SOCE!G8 -> 396122009
B16: TRADE AND OTHER PAYABLE | F16: 11 | G16: =NOTES!D93 -> 137536928
B18: TOTAL EQUITY AND LIBILITIES | G18: =G15+G16 -> 533658937

Sheet SOCE
A1: BLISSFUL NIGERIA PLC
A2: STATEMENT OF CHANGES IN EQUITY FOR THE PERIOD ENDED 31ST DECEMBER, 2023
D5: SHARE CAPITAL | E5: SHARE PREMIUM | F5: RETAINED EARNINGS | G5: TOTAL
A6: OPENING BALANCE | D6: 10000000 | E6: 200000000 | F6: 79095888 | G6: =SUM(D6:F6) -> 289095888
A7: PROFIT | D7: 0 | E7: 0 | F7: =SPL!F17 -> 107026121 | G7: =SUM(D7:F7) -> 107026121
A8: CLOSING BALANCE | D8: =SUM(D6:D7) -> 10000000 | E8: =SUM(E6:E7) -> 200000000 | F8: =SUM(F6:F7) -> 186122009 | G8: =SUM(G6:G7) -> 396122009

Sheet NOTES
A1: BLISSFUL NIGERIA PLC
A2: NOTES TO THE ACOUNT FOR THE PERIOD ENDED 31ST DECEMBER, 2023
A4: 1 | B4: REVENUE
B5: CONTRACT | D5: 4030173403
D6: =SUM(D5) -> 4030173403
A9: 2 | B9: COST OF SALES
B10: COST OF SALES | D10: 2763701495
B11: FREIGHT AND DELIVERY - COS | D11: 52252592
B12: SUPPLY - COS | D12: 461305162
D13: =SUM(D10:D12) -> 3277259249
A16: 3 | B16: SELLING AND DISTRIBUTION EXPENSES
B17: TRAVEL EXPENSES - GENERAL AND ADMIN EXPENSES | D17: 2099185
B18: TRAVEL EXPENSES - SELLING EXPENSES | D18: 8852900
B19: SHIPPING AND DELIVERY EXPENSE | D19: 301468
B20: FUEL- VEHICLE RUN | D20: 3808023
D21: =SUM(D17:D20) -> 15061576
A24: 4 | B24: GENERAL AND ADMIN EXPENSES
B25: TRAINING EXPENSES SERVICES | D25: 219248490
B26: BANK CHARGES | D26: 28027464
B27: CORPORATE SOCIAL RESPONSIBILITIES | D27: 3800500
B28: DIRECTORS EXPENSES | D28: 35478120
B29: DIRECTORS EXPENSES: DIRECTORS SALARY | D29: 30650000
B30: EQUIPMENT RENTAL | D30: 300000
B31: FUEL- GENERATOR RUN | D31: 7137894
B32: HEALTH, SAFETY & EVIRONMENT EXPENSES | D32: 391600
B33: INSUARANCE - GENERAL | D33: 330099
B34: LEAGSL AND PROFESSIONAL FEES | D34: 1522470
B35: LOCAL TRANSPORTATION | D35: 1086190
B36: MANAGEMENT COMPENSATION | D36: 1488046
... B51: UTILITIES | D51: 536480
D52: =SUM(D25:D51) -> 419862355
A55: 5 | B55: FINANCE COST
B56: INTEREST AND COMMISSION PAID | D56: 175276150
D57: =SUM(D56) -> 175276150
A60: 6 | B60: INCOME TAX
B61: COMPANY INCOME TAX | D61: 35687952
D62: =SUM(D61) -> 35687952
A64: 7 | B64: FIXED ASSET SCHEDULE
D65: FURNITURE & FITTINGS | E65: OFFICE EQUIPMENT | F65: MOTOR VEHICLE | G65: TOTAL
B66: COST | D66: 31250600 | E66: 150698250 | F66: 45025022 | G66: =SUM(D66:F66) -> 226973872
...

Sheet TRIAL BALANCE
A1: 2023 TRIAL BALANCE OF BLISSFUL NIGERIA PLC
A2: Description | B2: DEBIT | C2: CREDIT
A3: FURNITURE & FITTINGS | B3: 31250600
A4: OFFICE EQUIPMENT | B4: 150698250
A5: CAPITAL WORK IN PROGRESS | B5: 27525000
A6: MOTOR VEHICLE | B6: 45025022
A7: ACCUM DEP. FURNITURE & FITTING | C7: 12525000
A8: ACCUM DEP. OFFICE EQUIPMENT | C8: 102365952
A9: ACCUM DEP. MOTOR VEHICLE | C9: 20532655
A10: DIAMOND BANK | B10: 61244449
A11: GTB ACCOUNT | B11: 65311575
A12: ZENITH BANK | B12: 43414678
A13: FIRST BANK NIG | B13: 49662092
A14: UBA PLC | B14: 47064161
A15: PETTY CASH | B15: 256000
A16: ACCOUNT RECEIVABLE | B16: 147630717
A17: ACCOUNT PAYABLE | C17: 46952363
A18: BANK OVERDRAFT | C18: 90584565
A19: RETAINED EARNINGS | C19: 79095888
A20: SHARE PREMIUM | C20: 200000000
A21: SHARE CAPITAL | C21: 10000000
A22: CONTRACT | C22: 4030173403
A23: COST OF SALES | B23: 2763701495
A24: FREIGHT AND DELIVERY - COS | B24: 52252592
A25: SUPPLY - COS | B25: 461305162
A26: TRAINING EXPENSES SERVICES | B26: 219248490
A27: BANK CHARGES | B27: 28027464
A28: CORPORATE SOCIAL RESPONSIBILITIES | B28: 3800500
A29: DIRECTORS EXPENSES | B29: 35478120
A30: DIRECTORS EXPENSES: DIRECTORS SALARY | B30: 30650000
A31: EQUIPMENT RENTAL | B31: 300000
A32: FUEL- GENERATOR RUN | B32: 7137894
A33: FUEL- VEHICLE RUN | B33: 3808023
A34: HEALTH, SAFETY & EVIRONMENT EXPENSES | B34: 391600
... A58: COMPANY INCOME TAX | B58: 35687952
B59: =SUBTOTAL(109,cvg_35[DEBIT]) -> 4592229826 | C59: =SUBTOTAL(109,cvg.CDTLED) -> 4592229826
